Workbook
Name Avg_Distance_Per_Ride: 'Variable Cost Engine'!$B$9
Name Avg_Ride_Duration: 'Volume Engine'!$B$9
Name Cleaning_Per_Ride: 'Variable Cost Engine'!$B$6
Name Cost_Inflation: 'P&L Projection (12M)'!$B$7
Name Days_Per_Month: 'Volume Engine'!$B$8
Name Depreciation_Per_Vehicle: 'Fixed Cost Engine'!$B$6
Name Discount_Rate: 'Revenue Engine'!$B$7
Name Energy_Cost_Per_Km: 'Variable Cost Engine'!$B$10
Name Fleet_Growth: 'P&L Projection (12M)'!$B$5
Name Fleet_Minutes: 'Revenue Engine'!$B$11
Name Fleet_Rides: 'Fixed Cost Engine'!$B$12
Name Fleet_Size: 'Fixed Cost Engine'!$B$11
Name Hours_Per_Day: 'Volume Engine'!$B$7
Name Insurance_Per_Vehicle: 'Fixed Cost Engine'!$B$5
Name Logistics_Per_Vehicle: 'Variable Cost Engine'!$B$8
Name Maintenance_Per_Ride: 'Variable Cost Engine'!$B$5
Name Parking_Per_Vehicle: 'Variable Cost Engine'!$B$7
Name Platform_Overhead: 'Fixed Cost Engine'!$B$7
Name Price_Growth: 'P&L Projection (12M)'!$B$6
Name Price_Per_Minute: 'Revenue Engine'!$B$5
Name Unlock_Fee_Per_Ride: 'Revenue Engine'!$B$6
Name Utilization_Rate: 'Volume Engine'!$B$6

Sheet Cover
B3: Bolt Drive – FP&A Economic Model
B4: Driver-Based Financial Model & 12-Month Projection
B7: Purpose
B8: This model was built to understand the unit economics and operating leverage of a car-sharing business before stepping into the role.
B9: Rather than approaching the opportunity purely theoretically, I wanted to think through the key financial drivers in advance - revenue mechanics, utilization dynamics, cost structure, growth impact, and margin sensitivity.
B10: The objective is not to predict actual performance, but to demonstrate structured financial thinking around mobility economics.
B12: Scope
B13: • Operational volume engine (fleet × utilization)
B14: • Revenue build-up (gross to net)
B15: • Variable and fixed cost architecture
B16: • 12-month projection with growth & inflation
B17: • Sensitivity analysis on key drivers
... B24: Built for: Associate FP&A Analyst, Bolt Drive · Tallinn, Estonia

Sheet Dashboard
A1: BOLT DRIVE — FP&A DASHBOARD
A2: Active Scenario: | B2: =Assumptions!C2 -> Low | C2: Month 12 Snapshot + FY View
A4: Fleet Size | C4: Net Revenue | E4: EBITDA | G4: EBITDA Margin | I4: Revenue per Ride | K4: Total Cost per Ride
A5: ='P&L Projection (12M)'!M11 -> 390.48392 | C5: ='P&L Projection (12M)'!M12 -> 1046996.7 | E5: ='P&L Projection (12M)'!M21 -> -119094.82 | G5: ='P&L Projection (12M)'!M22 -> -0.11374899 | I5: ='P&L Projection (12M)'!M12/'P&L Projection (12M)'!M11/_xlfn.XLOOKUP("Rides per Vehicle per Month",tblVolumeEngine[Metric],tblVolumeEngine[Value]) -> 3.42 | K5: =('P&L Projection (12M)'!M13+'P&L Projection (12M)'!M19)/'P&L Projection (12M)'!M11/_xlfn.XLOOKUP("Rides per Vehicle per Month",tblVolumeEngine[Metric],tblVolumeEngine[Value]) -> 3.8090216
A6: vehicles (Month 12) | C6: € (Month 12) | E6: € (Month 12) | G6: % (Month 12) | I6: € per ride (Month 12) | K6: € per ride (Month 12)
A8: UNIT ECONOMICS — MONTH 12 SNAPSHOT
A9: Metric | B9: Value | C9: Unit
A10: Contribution Margin % | B10: ='P&L Projection (12M)'!M15 -> 0.11591917 | C10: %
A11: Variable Cost per Ride | B11: =_xlfn.XLOOKUP("Variable Cost per Ride",tblVariableCostEngine[Metric],tblVariableCostEngine[Value]) -> 2.3043878 | C11: € per ride
A12: Fixed Cost per Ride | B12: =_xlfn.XLOOKUP("Fixed Cost per Ride",tblFixedCostEngine[Metric],tblFixedCostEngine[Value]) -> 0.7662172 | C12: € per ride
A13: Rides per Vehicle per Month | B13: =_xlfn.XLOOKUP("Rides per Vehicle per Month",tblVolumeEngine[Metric],tblVolumeEngine[Value]) -> 784 | C13: rides/vehicle
A14: Utilization Rate | B14: =_xlfn.XLOOKUP("Utilization Rate",tblFleet[Driver Name],tblFleet[Active Scenario Value]) -> 0.5 | C14: %
A17: 12-MONTH TREND CHARTS
A19: Month | B19: Month 1 | C19: Month 2 | D19: Month 3 | E19: Month 4 | F19: Month 5 | G19: Month 6 | H19: Month 7 | I19: Month 8 | J19: Month 9 | K19: Month 10 | L19: Month 11 | M19: Month 12
A20: Revenue (€) | B20: ='P&L Projection (12M)'!B12 -> 938448 | C20: ='P&L Projection (12M)'!C12 -> 947832.48 | D20: ='P&L Projection (12M)'!D12 -> 957310.8 | E20: ='P&L Projection (12M)'!E12 -> 966883.91 | F20: ='P&L Projection (12M)'!F12 -> 976552.75 | G20: ='P&L Projection (12M)'!G12 -> 986318.28 | H20: ='P&L Projection (12M)'!H12 -> 996181.46 | I20: ='P&L Projection (12M)'!I12 -> 1006143.3 | ... M20: ='P&L Projection (12M)'!M12 -> 1046996.7
A21: EBITDA (€) | B21: ='P&L Projection (12M)'!B21 -> 95874 | C21: ='P&L Projection (12M)'!C21 -> 80416.559 | D21: ='P&L Projection (12M)'!D21 -> 64230.486 | E21: ='P&L Projection (12M)'!E21 -> 47288.374 | F21: ='P&L Projection (12M)'!F21 -> 29561.836 | G21: ='P&L Projection (12M)'!G21 -> 11021.47 | H21: ='P&L Projection (12M)'!H21 -> -8363.1767 | I21: ='P&L Projection (12M)'!I21 -> -28623.645 | ... M21: ='P&L Projection (12M)'!M21 -> -119094.82
A22: Fleet Size | B22: ='P&L Projection (12M)'!B11 -> 350 | C22: ='P&L Projection (12M)'!C11 -> 353.5 | D22: ='P&L Projection (12M)'!D11 -> 357.035 | E22: ='P&L Projection (12M)'!E11 -> 360.60535 | F22: ='P&L Projection (12M)'!F11 -> 364.2114 | G22: ='P&L Projection (12M)'!G11 -> 367.85352 | H22: ='P&L Projection (12M)'!H11 -> 371.53205 | I22: ='P&L Projection (12M)'!I11 -> 375.24737 | ... M22: ='P&L Projection (12M)'!M11 -> 390.48392
A23: EBITDA (€) | B23: ='P&L Projection (12M)'!B21 -> 95874 | C23: ='P&L Projection (12M)'!C21 -> 80416.559 | D23: ='P&L Projection (12M)'!D21 -> 64230.486 | E23: ='P&L Projection (12M)'!E21 -> 47288.374 | F23: ='P&L Projection (12M)'!F21 -> 29561.836 | G23: ='P&L Projection (12M)'!G21 -> 11021.47 | H23: ='P&L Projection (12M)'!H21 -> -8363.1767 | I23: ='P&L Projection (12M)'!I21 -> -28623.645 | ... M23: ='P&L Projection (12M)'!M21 -> -119094.82
A24: Fleet Size | B24: ='P&L Projection (12M)'!B11 -> 350 | C24: ='P&L Projection (12M)'!C11 -> 353.5 | D24: ='P&L Projection (12M)'!D11 -> 357.035 | E24: ='P&L Projection (12M)'!E11 -> 360.60535 | F24: ='P&L Projection (12M)'!F11 -> 364.2114 | G24: ='P&L Projection (12M)'!G11 -> 367.85352 | H24: ='P&L Projection (12M)'!H11 -> 371.53205 | I24: ='P&L Projection (12M)'!I11 -> 375.24737 | ... M24: ='P&L Projection (12M)'!M11 -> 390.48392
A34: RISK INSIGHT — EBITDA Margin: Price per Minute vs Utilization Rate
A35: FY EBITDA Margin sensitivity — Base Case highlighted in yellow. Green = better margin, Red = worse.
A36: Price/Min ↓ Util → | B36: ='Sensitivity Analysis'!B13 -> 0.5 | C36: ='Sensitivity Analysis'!C13 -> 0.575 | D36: ='Sensitivity Analysis'!D13 -> 0.65 | E36: ='Sensitivity Analysis'!E13 -> 0.725 | F36: ='Sensitivity Analysis'!F13 -> 0.8
A37: ='Sensitivity Analysis'!A14 -> 0.21 | B37: ='Sensitivity Analysis'!B14 -> 0.49 | C37: ='Sensitivity Analysis'!C14 -> 0.5119 | D37: ='Sensitivity Analysis'!D14 -> 0.5287 | E37: ='Sensitivity Analysis'!E14 -> 0.542 | F37: ='Sensitivity Analysis'!F14 -> 0.5528
A38: ='Sensitivity Analysis'!A15 -> 0.25 | B38: ='Sensitivity Analysis'!B15 -> 0.5597 | C38: ='Sensitivity Analysis'!C15 -> 0.5785 | D38: ='Sensitivity Analysis'!D15 -> 0.593 | E38: ='Sensitivity Analysis'!E15 -> 0.6045 | F38: ='Sensitivity Analysis'!F15 -> 0.6139
A39: ='Sensitivity Analysis'!A16 -> 0.29 | B39: ='Sensitivity Analysis'!B16 -> 0.6126 | C39: ='Sensitivity Analysis'!C16 -> 0.6292 | D39: ='Sensitivity Analysis'!D16 -> 0.6419 | E39: ='Sensitivity Analysis'!E16 -> 0.6521 | F39: ='Sensitivity Analysis'!F16 -> 0.6603
A40: ='Sensitivity Analysis'!A17 -> 0.33 | B40: ='Sensitivity Analysis'!B17 -> 0.6542 | C40: ='Sensitivity Analysis'!C17 -> 0.669 | D40: ='Sensitivity Analysis'!D17 -> 0.6804 | E40: ='Sensitivity Analysis'!E17 -> 0.6894 | F40: ='Sensitivity Analysis'!F17 -> 0.6967
A41: ='Sensitivity Analysis'!A18 -> 0.37 | B41: ='Sensitivity Analysis'!B18 -> 0.6877 | C41: ='Sensitivity Analysis'!C18 -> 0.701 | D41: ='Sensitivity Analysis'!D18 -> 0.7113 | E41: ='Sensitivity Analysis'!E18 -> 0.7195 | F41: ='Sensitivity Analysis'!F18 -> 0.7261

Sheet Assumptions
A1: BOLT DRIVE — FP&A MODEL ASSUMPTIONS
B2: Scenario Selector | C2: Low
A4: SECTION 1: Fleet & Utilization Drivers
A5: Driver Name | B5: Unit | C5: Base Case | D5: Low Case | E5: High Case | F5: Active Scenario Value
A6: Total Fleet Size | B6: vehicles | C6: 500 | D6: 350 | E6: 700 | F6: =IF($C$2="Base",tblFleet[[#This Row],[Base Case]],IF($C$2="Low",tblFleet[[#This Row],[Low Case]],IF($C$2="High",tblFleet[[#This Row],[High Case]],""))) -> 350
A7: Utilization Rate | B7: % | C7: 0.65 | D7: 0.5 | E7: 0.8 | F7: =IF($C$2="Base",tblFleet[[#This Row],[Base Case]],IF($C$2="Low",tblFleet[[#This Row],[Low Case]],IF($C$2="High",tblFleet[[#This Row],[High Case]],""))) -> 0.5
A8: Operating Hours per Day | B8: hours/day | C8: 18 | D8: 14 | E8: 22 | F8: =IF($C$2="Base",tblFleet[[#This Row],[Base Case]],IF($C$2="Low",tblFleet[[#This Row],[Low Case]],IF($C$2="High",tblFleet[[#This Row],[High Case]],""))) -> 14
A9: Average Ride Duration | B9: minutes | C9: 22 | D9: 15 | E9: 30 | F9: =IF($C$2="Base",tblFleet[[#This Row],[Base Case]],IF($C$2="Low",tblFleet[[#This Row],[Low Case]],IF($C$2="High",tblFleet[[#This Row],[High Case]],""))) -> 15
A10: Operating Days per Month | B10: days/month | C10: 30 | D10: 28 | E10: 31 | F10: =IF($C$2="Base",tblFleet[[#This Row],[Base Case]],IF($C$2="Low",tblFleet[[#This Row],[Low Case]],IF($C$2="High",tblFleet[[#This Row],[High Case]],""))) -> 28
A12: SECTION 2: Pricing Drivers
A13: Driver Name | B13: Unit | C13: Base Case | D13: Low Case | E13: High Case | F13: Active Scenario Value
A14: Price per Minute | B14: € per minute | C14: 0.29 | D14: 0.22 | E14: 0.38 | F14: =IF($C$2="Base",tblPricing[[#This Row],[Base Case]],IF($C$2="Low",tblPricing[[#This Row],[Low Case]],IF($C$2="High",tblPricing[[#This Row],[High Case]],""))) -> 0.22
A15: Unlock Fee per Ride | B15: € per ride | C15: 1 | D15: 0.5 | E15: 1.5 | F15: =IF($C$2="Base",tblPricing[[#This Row],[Base Case]],IF($C$2="Low",tblPricing[[#This Row],[Low Case]],IF($C$2="High",tblPricing[[#This Row],[High Case]],""))) -> 0.5
A16: Average Discount Rate | B16: % | C16: 0.05 | D16: 0.1 | E16: 0 | F16: =IF($C$2="Base",tblPricing[[#This Row],[Base Case]],IF($C$2="Low",tblPricing[[#This Row],[Low Case]],IF($C$2="High",tblPricing[[#This Row],[High Case]],""))) -> 0.1
A18: SECTION 3: Variable Cost Drivers
A19: Driver Name | B19: Unit | C19: Base Case | D19: Low Case | E19: High Case | F19: Active Scenario Value
A20: Maintenance Cost per Ride | B20: € per ride | C20: 0.85 | D20: 1.1 | E20: 0.65 | F20: =IF($C$2="Base",tblVariableCosts[[#This Row],[Base Case]],IF($C$2="Low",tblVariableCosts[[#This Row],[Low Case]],IF($C$2="High",tblVariableCosts[[#This Row],[High Case]],""))) -> 1.1
A21: Cleaning Cost per Ride | B21: € per ride | C21: 0.35 | D21: 0.5 | E21: 0.25 | F21: =IF($C$2="Base",tblVariableCosts[[#This Row],[Base Case]],IF($C$2="Low",tblVariableCosts[[#This Row],[Low Case]],IF($C$2="High",tblVariableCosts[[#This Row],[High Case]],""))) -> 0.5
A22: Parking Cost per Vehicle per Month | B22: € per vehicle/month | C22: 120 | D22: 160 | E22: 90 | F22: =IF($C$2="Base",tblVariableCosts[[#This Row],[Base Case]],IF($C$2="Low",tblVariableCosts[[#This Row],[Low Case]],IF($C$2="High",tblVariableCosts[[#This Row],[High Case]],""))) -> 160
A23: Logistics Cost per Vehicle per Month | B23: € per vehicle/month | C23: 80 | D23: 110 | E23: 60 | F23: =IF($C$2="Base",tblVariableCosts[[#This Row],[Base Case]],IF($C$2="Low",tblVariableCosts[[#This Row],[Low Case]],IF($C$2="High",tblVariableCosts[[#This Row],[High Case]],""))) -> 110
A24: Average Distance per Ride | B24: km/ride | C24: 6 | D24: 4 | E24: 8 | F24: =IF($C$2="Base",tblVariableCosts[[#This Row],[Base Case]],IF($C$2="Low",tblVariableCosts[[#This Row],[Low Case]],IF($C$2="High",tblVariableCosts[[#This Row],[High Case]],""))) -> 4
A25: Energy Cost per km | B25: €/km | C25: 0.12 | D25: 0.09 | E25: 0.16 | F25: =IF($C$2="Base",tblVariableCosts[[#This Row],[Base Case]],IF($C$2="Low",tblVariableCosts[[#This Row],[Low Case]],IF($C$2="High",tblVariableCosts[[#This Row],[High Case]],""))) -> 0.09
A27: SECTION 4: Fixed Cost Drivers
A28: Driver Name | B28: Unit | C28: Base Case | D28: Low Case | E28: High Case | F28: Active Scenario Value
A29: Insurance Cost per Vehicle per Month | B29: € per vehicle/month | C29: 95 | D29: 115 | E29: 75 | F29: =IF($C$2="Base",tblFixedCosts[[#This Row],[Base Case]],IF($C$2="Low",tblFixedCosts[[#This Row],[Low Case]],IF($C$2="High",tblFixedCosts[[#This Row],[High Case]],""))) -> 115
A30: Depreciation per Vehicle per Month | B30: € per vehicle/month | C30: 350 | D30: 400 | E30: 300 | F30: =IF($C$2="Base",tblFixedCosts[[#This Row],[Base Case]],IF($C$2="Low",tblFixedCosts[[#This Row],[Low Case]],IF($C$2="High",tblFixedCosts[[#This Row],[High Case]],""))) -> 400
A31: Platform Overhead Allocation per Month | B31: € per month | C31: 25000 | D31: 30000 | E31: 20000 | F31: =IF($C$2="Base",tblFixedCosts[[#This Row],[Base Case]],IF($C$2="Low",tblFixedCosts[[#This Row],[Low Case]],IF($C$2="High",tblFixedCosts[[#This Row],[High Case]],""))) -> 30000
A33: SECTION 5: Growth & Scenario Drivers
A34: Driver Name | B34: Unit | C34: Base Case | D34: Low Case | E34: High Case | F34: Active Scenario Value
A35: Monthly Fleet Growth Rate | B35: % | C35: 0.03 | D35: 0.01 | E35: 0.05 | F35: =IF($C$2="Base",tblGrowth[[#This Row],[Base Case]],IF($C$2="Low",tblGrowth[[#This Row],[Low Case]],IF($C$2="High",tblGrowth[[#This Row],[High Case]],""))) -> 0.01
A36: Monthly Price Growth Rate | B36: % | C36: 0.01 | D36: 0 | E36: 0.02 | F36: =IF($C$2="Base",tblGrowth[[#This Row],[Base Case]],IF($C$2="Low",tblGrowth[[#This Row],[Low Case]],IF($C$2="High",tblGrowth[[#This Row],[High Case]],""))) -> 0
A37: Monthly Cost Inflation Rate | B37: % | C37: 0.015 | D37: 0.025 | E37: 0.008 | F37: =IF($C$2="Base",tblGrowth[[#This Row],[Base Case]],IF($C$2="Low",tblGrowth[[#This Row],[Low Case]],IF($C$2="High",tblGrowth[[#This Row],[High Case]],""))) -> 0.025
A39: Color Key: | B39: Blue = Hardcoded Input | C39: Black = Formula / Scenario Logic | D39: Yellow cell = Scenario Selector

Sheet Volume Engine
A1: VOLUME ENGINE — OPERATIONAL ACTIVITY MODEL
A3: Linked Operational Inputs
A4: Driver Name | B4: Linked Value
A5: Total Fleet Size | B5: =_xlfn.XLOOKUP("Total Fleet Size",tblFleet[Driver Name],tblFleet[Active Scenario Value]) -> 350
A6: Utilization Rate | B6: =_xlfn.XLOOKUP("Utilization Rate",tblFleet[Driver Name],tblFleet[Active Scenario Value]) -> 0.5
A7: Operating Hours per Day | B7: =_xlfn.XLOOKUP("Operating Hours per Day",tblFleet[Driver Name],tblFleet[Active Scenario Value]) -> 14
A8: Operating Days per Month | B8: =_xlfn.XLOOKUP("Operating Days per Month",tblFleet[Driver Name],tblFleet[Active Scenario Value]) -> 28
A9: Average Ride Duration | B9: =_xlfn.XLOOKUP("Average Ride Duration",tblFleet[Driver Name],tblFleet[Active Scenario Value]) -> 15
A11: Core Activity & KPI Metrics
A12: Metric | B12: Unit | C12: Definition | D12: Value
A13: Available Minutes per Vehicle per Month | B13: minutes | C13: Hours_Per_Day × 60 × Days_Per_Month | D13: =Hours_Per_Day*60*Days_Per_Month -> 23520
A14: Available Minutes (Fleet) | B14: minutes | C14: Available Minutes per Vehicle × Fleet_Size | D14: =D13*Fleet_Size -> 8232000
A15: Used Minutes per Vehicle per Month | B15: minutes | C15: Available Minutes × Utilization_Rate | D15: =D13*Utilization_Rate -> 11760
A16: Total Used Minutes (Fleet) | B16: minutes | C16: Used Minutes per Vehicle × Fleet_Size | D16: =D15*Fleet_Size -> 4116000
A17: Total Rides (Fleet) | B17: rides | C17: Total Used Minutes ÷ Avg_Ride_Duration | D17: =D16/Avg_Ride_Duration -> 274400
A18: Rides per Vehicle per Month | B18: rides | C18: Total Rides ÷ Fleet_Size | D18: =D17/Fleet_Size -> 784
A19: ── KPI & Diagnostic Metrics ──
A20: Used Hours per Vehicle per Day | B20: hours | C20: Utilization_Rate × Hours_Per_Day | D20: =Utilization_Rate*Hours_Per_Day -> 7
A21: Used Minutes per Vehicle per Day | B21: minutes | C21: Used Minutes per Vehicle per Month ÷ Days_Per_Month | D21: =D15/Days_Per_Month -> 420
A22: Rides per Vehicle per Day | B22: rides | C22: Rides per Vehicle per Month ÷ Days_Per_Month | D22: =D18/Days_Per_Month -> 28
A23: Average Minutes per Ride (Sanity Check) | B23: minutes | C23: Total Used Minutes ÷ Total Rides | D23: =D16/D17 -> 15
A24: Utilization Check | B24: % | C24: Used Minutes per Vehicle ÷ Available Minutes per Vehicle | D24: =D15/D13 -> 0.5
A26: Color Key: | B26: Green = Linked from Assumptions (via tblFleet) | C26: Black = Formula (references named inputs or prior rows)

Sheet Revenue Engine
A1: REVENUE ENGINE — SCENARIO-DRIVEN REVENUE MODEL
A3: Linked Pricing Inputs
A4: Driver Name | B4: Linked Value
A5: Price per Minute | B5: =_xlfn.XLOOKUP("Price per Minute",tblPricing[Driver Name],tblPricing[Active Scenario Value]) -> 0.22
A6: Unlock Fee per Ride | B6: =_xlfn.XLOOKUP("Unlock Fee per Ride",tblPricing[Driver Name],tblPricing[Active Scenario Value]) -> 0.5
A7: Average Discount Rate | B7: =_xlfn.XLOOKUP("Average Discount Rate",tblPricing[Driver Name],tblPricing[Active Scenario Value]) -> 0.1
A9: Linked Volume Outputs
A10: Metric | B10: Linked Value
A11: Total Used Minutes (Fleet) | B11: =_xlfn.XLOOKUP("Total Used Minutes (Fleet)",tblVolumeEngine[Metric],tblVolumeEngine[Value]) -> 4116000
A12: Total Rides (Fleet) | B12: =_xlfn.XLOOKUP("Total Rides (Fleet)",tblVolumeEngine[Metric],tblVolumeEngine[Value]) -> 274400
A14: Revenue Calculations
A15: Metric | B15: Unit | C15: Definition | D15: Value
A16: Fleet Minutes (for Revenue Calc) | B16: minutes | C16: Linked from Volume Engine | D16: =Fleet_Minutes -> 4116000
A17: Fleet Rides (for Revenue Calc) | B17: rides | C17: Linked from Volume Engine | D17: =Fleet_Rides -> 274400
A18: Gross Time-Based Revenue | B18: € | C18: Fleet Minutes × Price per Minute | D18: =D16*Price_Per_Minute -> 905520
A19: Gross Unlock Revenue | B19: € | C19: Fleet Rides × Unlock Fee per Ride | D19: =D17*Unlock_Fee_Per_Ride -> 137200
A20: Gross Revenue | B20: € | C20: Time-Based Revenue + Unlock Revenue | D20: =D18+D19 -> 1042720
A21: Gross Revenue per Ride | B21: € | C21: Gross Revenue ÷ Fleet Rides | D21: =D20/Fleet_Rides -> 3.8
A22: Discount Rate (Reference) | B22: % | C22: Linked from Pricing Inputs | D22: =Discount_Rate -> 0.1
A23: Discount Amount | B23: € | C23: Gross Revenue × Discount Rate | D23: =D20*Discount_Rate -> 104272
A24: Net Revenue | B24: € | C24: Gross Revenue − Discount Amount | D24: =D20-D23 -> 938448
A25: Revenue per Ride (Net) | B25: € | C25: Net Revenue ÷ Fleet Rides | D25: =D24/Fleet_Rides -> 3.42
A26: Revenue per Minute (Net) | B26: € | C26: Net Revenue ÷ Fleet Minutes | D26: =D24/Fleet_Minutes -> 0.228
A27: Revenue per Vehicle per Month (Net) | B27: € | C27: Net Revenue ÷ Fleet Size | D27: =D24/Fleet_Size -> 2681.28
A29: Color Key: | B29: Green = Linked from Assumptions or Volume Engine | C29: Black = Formula (references named inputs or prior rows)

Sheet Variable Cost Engine
A1: VARIABLE COST ENGINE — SCENARIO-DRIVEN COST MODEL
A3: Linked Variable Cost Inputs
A4: Driver Name | B4: Linked Value
A5: Maintenance Cost per Ride | B5: =_xlfn.XLOOKUP("Maintenance Cost per Ride",tblVariableCosts[Driver Name],tblVariableCosts[Active Scenario Value]) -> 1.1
A6: Cleaning Cost per Ride | B6: =_xlfn.XLOOKUP("Cleaning Cost per Ride",tblVariableCosts[Driver Name],tblVariableCosts[Active Scenario Value]) -> 0.5
A7: Parking Cost per Vehicle per Month | B7: =_xlfn.XLOOKUP("Parking Cost per Vehicle per Month",tblVariableCosts[Driver Name],tblVariableCosts[Active Scenario Value]) -> 160
A8: Logistics Cost per Vehicle per Month | B8: =_xlfn.XLOOKUP("Logistics Cost per Vehicle per Month",tblVariableCosts[Driver Name],tblVariableCosts[Active Scenario Value]) -> 110
A9: Average Distance per Ride | B9: =_xlfn.XLOOKUP("Average Distance per Ride",tblVariableCosts[Driver Name],tblVariableCosts[Active Scenario Value]) -> 4
A10: Energy Cost per km | B10: =_xlfn.XLOOKUP("Energy Cost per km",tblVariableCosts[Driver Name],tblVariableCosts[Active Scenario Value]) -> 0.09
A12: Linked Volume Outputs
A13: Metric | B13: Linked Value
A14: Total Rides (Fleet) | B14: =_xlfn.XLOOKUP("Total Rides (Fleet)",tblVolumeEngine[Metric],tblVolumeEngine[Value]) -> 274400
A15: Total Fleet Size | B15: =Fleet_Size -> 350
A17: Variable Cost Calculations
A18: Metric | B18: Unit | C18: Definition | D18: Value
A19: Per-Ride Variable Costs
A20: Maintenance Cost (Total) | B20: € | C20: Fleet_Rides × Maintenance_Per_Ride | D20: =Fleet_Rides*Maintenance_Per_Ride -> 301840
A21: Cleaning Cost (Total) | B21: € | C21: Fleet_Rides × Cleaning_Per_Ride | D21: =Fleet_Rides*Cleaning_Per_Ride -> 137200
A22: Energy Cost (Total) | B22: € | C22: Fleet_Rides × Avg_Distance_Per_Ride × Energy_Cost_Per_Km | D22: =Fleet_Rides*Avg_Distance_Per_Ride*Energy_Cost_Per_Km -> 98784
A23: Total Per-Ride Variable Costs | B23: € | C23: Maintenance + Cleaning + Energy | D23: =D20+D21+D22 -> 537824
A24: Per-Vehicle Variable Costs
A25: Parking Cost (Total) | B25: € | C25: Fleet_Size × Parking_Per_Vehicle | D25: =Fleet_Size*Parking_Per_Vehicle -> 56000
A26: Logistics Cost (Total) | B26: € | C26: Fleet_Size × Logistics_Per_Vehicle | D26: =Fleet_Size*Logistics_Per_Vehicle -> 38500
A27: Total Per-Vehicle Variable Costs | B27: € | C27: Parking + Logistics | D27: =D25+D26 -> 94500
A28: Total Variable Costs | B28: € | C28: Per-Ride + Per-Vehicle Variable Costs | D28: =D23+D27 -> 632324
A29: ── Unit Economic KPIs ──
A30: Variable Cost per Ride | B30: € | C30: Total Variable Costs ÷ Fleet_Rides | D30: =D28/Fleet_Rides -> 2.3043878
A31: Variable Cost per Vehicle per Month | B31: € | C31: Total Variable Costs ÷ Fleet_Size | D31: =D28/Fleet_Size -> 1806.64
A32: Direct Cost per Ride (Ride-Only Costs) | B32: € | C32: Total Per-Ride Variable Costs ÷ Fleet_Rides | D32: =D23/Fleet_Rides -> 1.96
A34: Color Key: | B34: Green = Linked from Assumptions or Volume Engine | C34: Black = Formula (named inputs or prior rows)

Sheet Fixed Cost Engine
A1: FIXED COST ENGINE — SCENARIO-DRIVEN COST MODEL
A3: Linked Fixed Cost Inputs
A4: Driver Name | B4: Linked Value
A5: Insurance Cost per Vehicle per Month | B5: =_xlfn.XLOOKUP("Insurance Cost per Vehicle per Month",tblFixedCosts[Driver Name],tblFixedCosts[Active Scenario Value]) -> 115
A6: Depreciation per Vehicle per Month | B6: =_xlfn.XLOOKUP("Depreciation per Vehicle per Month",tblFixedCosts[Driver Name],tblFixedCosts[Active Scenario Value]) -> 400
A7: Platform Overhead Allocation per Month | B7: =_xlfn.XLOOKUP("Platform Overhead Allocation per Month",tblFixedCosts[Driver Name],tblFixedCosts[Active Scenario Value]) -> 30000
A9: Linked Volume Outputs
A10: Metric | B10: Linked Value
A11: Total Fleet Size | B11: =_xlfn.XLOOKUP("Total Fleet Size",tblFleet[Driver Name],tblFleet[Active Scenario Value]) -> 350
A12: Total Rides (Fleet) | B12: =_xlfn.XLOOKUP("Total Rides (Fleet)",tblVolumeEngine[Metric],tblVolumeEngine[Value]) -> 274400
A14: Fixed Cost Calculations
A15: Metric | B15: Unit | C15: Definition | D15: Value
A16: Per-Vehicle Fixed Costs
A17: Insurance Cost (Total) | B17: € | C17: Fleet_Size × Insurance_Per_Vehicle | D17: =Fleet_Size*Insurance_Per_Vehicle -> 40250
A18: Depreciation Cost (Total) | B18: € | C18: Fleet_Size × Depreciation_Per_Vehicle | D18: =Fleet_Size*Depreciation_Per_Vehicle -> 140000
A19: Vehicle Fixed Costs (Total) | B19: € | C19: Insurance + Depreciation | D19: =D17+D18 -> 180250
A20: Corporate Fixed Costs
A21: Platform Overhead | B21: € | C21: Linked from Assumptions | D21: =Platform_Overhead -> 30000
A22: Total Fixed Costs | B22: € | C22: Per-Vehicle Fixed + Platform Overhead | D22: =D19+D21 -> 210250
A23: ── KPI Metrics ──
A24: Fixed Cost per Vehicle per Month | B24: € | C24: Total Fixed Costs ÷ Fleet_Size | D24: =D22/Fleet_Size -> 600.71429
A25: Fixed Cost per Ride | B25: € | C25: Total Fixed Costs ÷ Fleet_Rides | D25: =D22/Fleet_Rides -> 0.7662172
A27: Color Key: | B27: Green = Linked from Assumptions or Volume Engine | C27: Black = Formula (named inputs or prior rows)

Sheet P&L Projection (12M)
A1: P&L PROJECTION — 12-MONTH SCENARIO MODEL
A3: Linked Growth Drivers
A4: Driver Name | B4: Linked Value
A5: Monthly Fleet Growth Rate | B5: =_xlfn.XLOOKUP("Monthly Fleet Growth Rate",tblGrowth[Driver Name],tblGrowth[Active Scenario Value]) -> 0.01
A6: Monthly Price Growth Rate | B6: =_xlfn.XLOOKUP("Monthly Price Growth Rate",tblGrowth[Driver Name],tblGrowth[Active Scenario Value]) -> 0
A7: Monthly Cost Inflation Rate | B7: =_xlfn.XLOOKUP("Monthly Cost Inflation Rate",tblGrowth[Driver Name],tblGrowth[Active Scenario Value]) -> 0.025
A9: P&L Projection — Monthly Build
A10: Metric | B10: Month 1 | C10: Month 2 | D10: Month 3 | E10: Month 4 | F10: Month 5 | G10: Month 6 | H10: Month 7 | I10: Month 8 | J10: Month 9 | K10: Month 10 | L10: Month 11 | M10: Month 12 | N10: FY Total
A11: Fleet Size (vehicles) | B11: =_xlfn.XLOOKUP("Total Fleet Size",tblFleet[Driver Name],tblFleet[Active Scenario Value]) -> 350 | C11: =B11*(1+Fleet_Growth) -> 353.5 | D11: =C11*(1+Fleet_Growth) -> 357.035 | E11: =D11*(1+Fleet_Growth) -> 360.60535 | F11: =E11*(1+Fleet_Growth) -> 364.2114 | G11: =F11*(1+Fleet_Growth) -> 367.85352 | H11: =G11*(1+Fleet_Growth) -> 371.53205 | I11: =H11*(1+Fleet_Growth) -> 375.24737 | J11: =I11*(1+Fleet_Growth) -> 378.99985 | ... M11: =L11*(1+Fleet_Growth) -> 390.48392 | N11: =M11 -> 390.48392
A12: Revenue (Net) | B12: =_xlfn.XLOOKUP("Net Revenue",tblRevenueEngine[Metric],tblRevenueEngine[Value]) -> 938448 | C12: =B12*(1+Fleet_Growth)*(1+Price_Growth) -> 947832.48 | D12: =C12*(1+Fleet_Growth)*(1+Price_Growth) -> 957310.8 | E12: =D12*(1+Fleet_Growth)*(1+Price_Growth) -> 966883.91 | F12: =E12*(1+Fleet_Growth)*(1+Price_Growth) -> 976552.75 | G12: =F12*(1+Fleet_Growth)*(1+Price_Growth) -> 986318.28 | H12: =G12*(1+Fleet_Growth)*(1+Price_Growth) -> 996181.46 | I12: =H12*(1+Fleet_Growth)*(1+Price_Growth) -> 1006143.3 | J12: =I12*(1+Fleet_Growth)*(1+Price_Growth) -> 1016204.7 | ... M12: =L12*(1+Fleet_Growth)*(1+Price_Growth) -> 1046996.7 | N12: =SUM(B12:M12) -> 11901870
A13: Variable Costs | B13: =_xlfn.XLOOKUP("Total Variable Costs",tblVariableCostEngine[Metric],tblVariableCostEngine[Value]) -> 632324 | C13: =B13*(1+Fleet_Growth)*(1+Cost_Inflation) -> 654613.42 | D13: =C13*(1+Fleet_Growth)*(1+Cost_Inflation) -> 677688.54 | E13: =D13*(1+Fleet_Growth)*(1+Cost_Inflation) -> 701577.07 | F13: =E13*(1+Fleet_Growth)*(1+Cost_Inflation) -> 726307.66 | G13: =F13*(1+Fleet_Growth)*(1+Cost_Inflation) -> 751910 | H13: =G13*(1+Fleet_Growth)*(1+Cost_Inflation) -> 778414.83 | I13: =H13*(1+Fleet_Growth)*(1+Cost_Inflation) -> 805853.95 | J13: =I13*(1+Fleet_Growth)*(1+Cost_Inflation) -> 834260.3 | ... M13: =L13*(1+Fleet_Growth)*(1+Cost_Inflation) -> 925629.73 | N13: =SUM(B13:M13) -> 9246359.8
A14: Contribution Margin | B14: =B12-B13 -> 306124 | C14: =C12-C13 -> 293219.06 | D14: =D12-D13 -> 279622.26 | E14: =E12-E13 -> 265306.85 | F14: =F12-F13 -> 250245.1 | G14: =G12-G13 -> 234408.28 | H14: =H12-H13 -> 217766.63 | I14: =I12-I13 -> 200289.32 | ... M14: =M12-M13 -> 121367 | N14: =SUM(B14:M14) -> 2655509.8
A15: Contribution Margin % | B15: =B14/B12 -> 0.32620241 | C15: =C14/C12 -> 0.30935747 | D15: =D14/D12 -> 0.29209141 | E15: =E14/E12 -> 0.27439369 | F15: =F14/F12 -> 0.25625354 | G15: =G14/G12 -> 0.23765987 | H15: =H14/H12 -> 0.21860137 | I15: =I14/I12 -> 0.1990664 | ... N15: =N14/N12 -> 0.22311703
A17: Vehicle Fixed Costs (Total) | B17: =_xlfn.XLOOKUP("Vehicle Fixed Costs (Total)",tblFixedCostEngine[Metric],tblFixedCostEngine[Value]) -> 180250 | C17: =B17*(1+Fleet_Growth) -> 182052.5 | D17: =C17*(1+Fleet_Growth) -> 183873.02 | E17: =D17*(1+Fleet_Growth) -> 185711.76 | F17: =E17*(1+Fleet_Growth) -> 187568.87 | G17: =F17*(1+Fleet_Growth) -> 189444.56 | H17: =G17*(1+Fleet_Growth) -> 191339.01 | I17: =H17*(1+Fleet_Growth) -> 193252.4 | J17: =I17*(1+Fleet_Growth) -> 195184.92 | ... M17: =L17*(1+Fleet_Growth) -> 201099.22 | N17: =SUM(B17:M17) -> 2286021.2
A18: Platform Overhead | B18: =_xlfn.XLOOKUP("Platform Overhead",tblFixedCostEngine[Metric],tblFixedCostEngine[Value]) -> 30000 | C18: =B18*(1+Cost_Inflation) -> 30750 | D18: =C18*(1+Cost_Inflation) -> 31518.75 | E18: =D18*(1+Cost_Inflation) -> 32306.719 | F18: =E18*(1+Cost_Inflation) -> 33114.387 | G18: =F18*(1+Cost_Inflation) -> 33942.246 | H18: =G18*(1+Cost_Inflation) -> 34790.803 | I18: =H18*(1+Cost_Inflation) -> 35660.573 | J18: =I18*(1+Cost_Inflation) -> 36552.087 | ... M18: =L18*(1+Cost_Inflation) -> 39362.6 | N18: =SUM(B18:M18) -> 413866.59
A19: Total Fixed Costs | B19: =B17+B18 -> 210250 | C19: =C17+C18 -> 212802.5 | D19: =D17+D18 -> 215391.77 | E19: =E17+E18 -> 218018.47 | F19: =F17+F18 -> 220683.26 | G19: =G17+G18 -> 223386.81 | H19: =H17+H18 -> 226129.81 | I19: =I17+I18 -> 228912.97 | ... M19: =M17+M18 -> 240461.82 | N19: =SUM(B19:M19) -> 2699887.8
A21: EBITDA | B21: =B14-B19 -> 95874 | C21: =C14-C19 -> 80416.559 | D21: =D14-D19 -> 64230.486 | E21: =E14-E19 -> 47288.374 | F21: =F14-F19 -> 29561.836 | G21: =G14-G19 -> 11021.47 | H21: =H14-H19 -> -8363.1767 | I21: =I14-I19 -> -28623.645 | ... M21: =M14-M19 -> -119094.82 | N21: =SUM(B21:M21) -> -44377.932
A22: EBITDA Margin % | B22: =B21/B12 -> 0.10216229 | C22: =C21/C12 -> 0.084842586 | D22: =D21/D12 -> 0.067094705 | E22: =E21/E12 -> 0.048908016 | F22: =F21/F12 -> 0.030271622 | G22: =G21/G12 -> 0.011174354 | H22: =H21/H12 -> -0.0083952342 | I22: =I21/I12 -> -0.028448876 | ... N22: =N21/N12 -> -0.0037286522
A24: Color Key: | B24: Green = Linked from tblGrowth (Assumptions) | C24: Black = Formula (prior month × growth rates)

Sheet Sensitivity Analysis
A1: SENSITIVITY ANALYSIS — FY TOTAL (12-MONTH)
A2: Each table shows FY Total output across a range of two drivers. Yellow cell = Base Case. Change Scenario in Assumptions to shift all base values.
A4: TABLE 1A — FY Net Revenue (€) | Price per Minute vs Utilization Rate
A5: Price/Min ↓ Util Rate → | B5: 0.5 | C5: 0.575 | D5: 0.65 | E5: 0.725 | F5: 0.8
A6: 0.21 | B6: 29286761 | C6: 33679775 | D6: 38072790 | E6: 42465804 | F6: 46858818
A7: 0.25 | B7: 33919671 | C7: 39007622 | D7: 44095572 | E7: 49183523 | F7: 54271474
A8: 0.29 | B8: 38552581 | C8: 44335468 | D8: 50118355 | E8: 55901242 | F8: 61684129
A9: 0.33 | B9: 43185491 | C9: 49663314 | D9: 56141138 | E9: 62618961 | F9: 69096785
A10: 0.37 | B10: 47818400 | C10: 54991160 | D10: 62163920 | E10: 69336680 | F10: 76509441
A12: TABLE 1B — FY EBITDA Margin (%) | Price per Minute vs Utilization Rate
A13: Price/Min ↓ Util Rate → | B13: 0.5 | C13: 0.575 | D13: 0.65 | E13: 0.725 | F13: 0.8
A14: 0.21 | B14: 0.49 | C14: 0.5119 | D14: 0.5287 | E14: 0.542 | F14: 0.5528
A15: 0.25 | B15: 0.5597 | C15: 0.5785 | D15: 0.593 | E15: 0.6045 | F15: 0.6139
A16: 0.29 | B16: 0.6126 | C16: 0.6292 | D16: 0.6419 | E16: 0.6521 | F16: 0.6603
A17: 0.33 | B17: 0.6542 | C17: 0.669 | D17: 0.6804 | E17: 0.6894 | F17: 0.6967
A18: 0.37 | B18: 0.6877 | C18: 0.701 | D18: 0.7113 | E18: 0.7195 | F18: 0.7261
A20: TABLE 2A — FY Net Revenue (€) | Fleet Growth vs Price Growth
A21: Fleet Gr. ↓ Price Gr. → | B21: 0 | C21: 0.005 | D21: 0.01 | E21: 0.015 | F21: 0.02
A22: 0 | B22: 40268635 | C22: 41242106 | D22: 42248586 | E22: 43289205 | F22: 44365128
A23: 0.015 | B23: 43762648 | C23: 44854985 | D23: 45984954 | E23: 47153855 | F23: 48363031
A24: 0.03 | B24: 47624471 | C24: 48849983 | D24: 50118355 | E24: 51431080 | F24: 52789702
A25: 0.045 | B25: 51892954 | C25: 53267575 | D25: 54690960 | E25: 56164822 | F25: 57690935
A26: 0.06 | B26: 56610791 | C26: 58152247 | D26: 59749127 | E26: 61403395 | F26: 63117083
A28: TABLE 2B — FY EBITDA Margin (%) | Fleet Growth vs Price Growth
A29: Fleet Gr. ↓ Price Gr. → | B29: 0 | C29: 0.005 | D29: 0.01 | E29: 0.015 | F29: 0.02
A30: 0 | B30: 0.6219 | C30: 0.6309 | D30: 0.6397 | E30: 0.6483 | F30: 0.6569
A31: 0.015 | B31: 0.6226 | C31: 0.6318 | D31: 0.6408 | E31: 0.6497 | F31: 0.6585
A32: 0.03 | B32: 0.6232 | C32: 0.6326 | D32: 0.6419 | E32: 0.6511 | F32: 0.6601
A33: 0.045 | B33: 0.6238 | C33: 0.6335 | D33: 0.643 | E33: 0.6524 | F33: 0.6616
A34: 0.06 | B34: 0.6243 | C34: 0.6342 | D34: 0.644 | E34: 0.6536 | F34: 0.663
A36: TABLE 3A — FY Net Revenue (€) | Cost Inflation vs Fleet Growth
A37: Cost Inf. ↓ Fleet Gr. → | B37: 0 | C37: 0.015 | D37: 0.03 | E37: 0.045 | F37: 0.06
A38: 0 | B38: 42248586 | C38: 45984954 | D38: 50118355 | E38: 54690960 | F38: 59749127
A39: 0.0075 | B39: 42248586 | C39: 45984954 | D39: 50118355 | E39: 54690960 | F39: 59749127
A40: 0.015 | B40: 42248586 | C40: 45984954 | D40: 50118355 | E40: 54690960 | F40: 59749127
A41: 0.0225 | B41: 42248586 | C41: 45984954 | D41: 50118355 | E41: 54690960 | F41: 59749127
A42: 0.03 | B42: 42248586 | C42: 45984954 | D42: 50118355 | E42: 54690960 | F42: 59749127
A44: TABLE 3B — FY EBITDA Margin (%) | Cost Inflation vs Fleet Growth
A45: Cost Inf. ↓ Fleet Gr. → | B45: 0 | C45: 0.015 | D45: 0.03 | E45: 0.045 | F45: 0.06
A46: 0 | B46: 0.6403 | C46: 0.6414 | D46: 0.6425 | E46: 0.6435 | F46: 0.6445
...
